Workbook

Sheet Summary
A1: Swarm PoC - network fault harness: results summary
A2: Every figure below is a formula over the data sheets, not a typed-in number. Full write-up: docs/findings.md
A4: Result | B4: Value | C4: Where from
A5: Concurrency: mean measured / closed-loop bound | B5: =AVERAGE('exp1 Concurrency'!P5:P14) -> 0.88012956 | C5: exp1. The bound tracks measurement across a 32x range of G.
A6: Concurrency: worst measured / closed-loop bound | B6: =MIN('exp1 Concurrency'!P5:P14) -> 0.8554382 | C6: exp1
A7: Concurrency: total failed requests | B7: =SUM('exp1 Concurrency'!M5:M14) -> 0 | C7: exp1. Zero across the whole sweep.
A8: Concurrency: peak measured throughput (tok/s) | B8: =MAX('exp1 Concurrency'!C5:C14) -> 92.212801 | C8: exp1. Against a capacity bound in column F.
A9: Delay: worst |slope error| vs predicted D | B9: =MAX('exp2 Delay'!F25:F28) -> 0.001888625 | C9: exp2, over the per-depth |error| column.
A10: Delay: lowest R2 of the linear fit | B10: =MIN('exp2 Delay'!G25:G28) -> 0.99999076 | C10: exp2. Latency is linear in per-hop delay with slope D.
A11: Mode check: median |error|, synthetic on nominal bandwidth | B11: =MEDIAN('exp7 Mode check'!M8:M10) -> 0.80718136 | C11: exp7. Tier reference bandwidths are ratios, not achievable values.
A12: Mode check: median |error|, synthetic on fitted B_eff | B12: =MEDIAN('exp7 Mode check'!M5:M7) -> 0.20547303 | C12: exp7. Good at G=1, degrades with concurrency: no CPU contention.
A13: Mode check: fitted effective bandwidth (GB/s) | B13: =MAX('exp7 Mode check'!L5:L10) -> 6.8997309 | C13: exp7. Against a tier-2 nominal of 45 GB/s.
A15: Read these with the limits in docs/findings.md
A16: - One host: all containers share its CPU and memory bandwidth; runs are therefore sequential.
A17: - Tier emulation preserves ratios, not absolute device speeds - exp7 measures the gap as 6.5x for tier 2.
A18: - Synthetic mode models neither CPU contention nor prefill cost, so it over-predicts throughput by 1.6-2.2x even calibrated.
A19: - Virtual-engine results are valid for latency, compute, network and aggregate queueing; not for queue-wait distribution or tail latency.
A20: - Predictions carry no fitted correction: the measured/predicted ratio is the harness's own cost, reported rather than subtracted out.

Sheet Experiment design
A1: Experiment design - what varied, what was held constant, and why
A2: Read this before the data sheets. Where a value had to be chosen rather than swept, the reason is given: a defaulted constant that happens to bind a result is the easiest way to draw a wrong conclusion from a sweep.
A4: sheet | B4: experiment (value in data) | C4: title | D4: question asked | E4: varied | F4: held constant | G4: runs | H4: engine | I4: mode | J4: design notes and why
A5: exp1 Concurrency | B5: 1_concurrency | C5: Concurrency sweep | D5: How does throughput track the utilisation curve as concurrency rises, and where does the system stop scaling? | E5: G: 1, 2, 3, 4, 6, 8, 12, 16, 24, 32 | F5: D=3, W=2, N=6, all tier 2; per-hop delay 5 ms; 500 Mbit/s; prompt 32, gen 8; no churn; hop timeout 2000 ms | G5: 10 | H5: container | I5: synthetic | J5: N=6 so the sweep crosses G=N well inside the range. No churn: a stalled stream would show up as lost throughput that has nothing to do with G. The hop timeout is deliberately generous because a saturated closed-loop system's latency grows as G/X; a shorter one caused tokens to time out, retry, add load and collapse throughput to a fifth of the plateau.
A6: exp2 Delay | B6: 2_delay | C6: Delay sweep | D6: How does per-hop latency accumulate with pipeline depth and link delay? | E6: D: 2, 3, 4, 6 crossed with per-hop delay: 1, 5, 25, 50 ms | F6: W=1, G=1, all tier 2; 500 Mbit/s; prompt 32, gen 8; no churn | G6: 16 | H6: container | I6: synthetic | J6: W=1 and G=1 deliberately: replicas would let queueing confound the hop term, and any concurrency above 1 adds queue wait to the very quantity being decomposed. Total compute is fixed and split across D stages, so compute stays about 60 ms while the network term grows with D. Only the tier-2 link is swept, so the expected slope is D, not D+1: the gateway's entry hop is held fixed and lands in the intercept.
A7: exp4 Failover | B7: 4_failover | C7: Disconnection and failover | D7: How fast is a node loss detected and routed around, and at what cost in failed requests? | E7: Arm W_x_heartbeat: W in {1,2,3} crossed with heartbeat in {250,500,1000} ms. Arm hop_timeout: timeout in {250,1000,2000,5000} ms at W=2, heartbeat 500 ms | F7: D=3, G=6, all tier 2; delay 5 ms; death_after = 4x heartbeat; one kill of a middle-stage replica at t=20 s; duration 50 s | G7: 13 | H7: container | I7: synthetic | J7: The victim is always a middle stage: stage 0 is reached directly from the gateway and the last stage reports back to it, so a middle stage is the case where an upstream worker has to discover the failure. The W=1 arm is the control and has the last-replica guard disabled, or the fault would be silently suppressed and the run would measure nothing. The second arm exists because bring-up showed recovery time tracking the client timeout rather than the detection threshold.
A8: exp7 Mode check | B8: 7_mode_check | C8: Mode check (real vs synthetic) | D8: Do synthetic timings track real ones? This is the experiment that licenses every other synthetic result. | E8: G: 1, 2, 4 crossed with arm: real, synthetic on nominal bandwidth, synthetic on fitted B_eff | F8: D=3, W=1, all tier 2; Qwen2.5-0.5B split 8/8/8 layers; CPU float32; greedy decoding; prompt 32, gen 8; hop timeout 30000 ms; duration 90 s | G8: 9 | H8: container | I8: real and synthetic | J8: Three phases in order: real runs first, then the effective memory bandwidth fitted from them, then synthetic arms on both the nominal and the fitted bandwidth. Comparing a real arm against a synthetic arm fed the tier table's nominal figure would measure that mismatch rather than synthetic mode's fidelity. The large timeout is required because the first token of each request is a prefill, roughly 32x a decode step.
A9: exp1s Report scale | B9: 1s_concurrency_scale | C9: Concurrency at research-report scale | D9: Does the utilisation ramp hold at the research report's own scale, and where does it break? | E9: G: 1, 10, 50, 100, 250, 500, 1000, 1500, 2000 | F9: D=50, W=20, N=1000, all tier 1; delay 1 ms; report_moe (1T MoE, 60B active, INT4); gen 4; no churn; per-hop logging off; duration 180 s | G9: 9 | H9: virtual | I9: synthetic | J9: A reconstruction of the research report's appendix example A, whose figures were derived independently of this code, so agreement is a real check rather than a tautology. N=1000 is about 16x what this host can run as containers, so this is virtual-engine only and is trustworthy only on the axes the engine comparison validates. Per-hop logging is off: at D=50 it would be 51 rows per token.

Sheet Cost model & tiers
A1: The cost model under test, and the emulated device tiers
A2: Everything this harness predicts derives from the expressions below. Measurements are compared against them, never fitted to them.
A4: Governing expressions
A5: quantity | B5: expression | C5: what it means, and what this harness measured about it
A6: T_token | B6: (P_a*b + s*q)/B + D*(l + a/beta) | C6: Per-token latency. The first term uses ONE device's bandwidth B, not the sum over devices: adding devices never shrinks it. Measured here: the D*(l + a/beta) term is confirmed to within 0.2% (experiment 2).
A7: X_max | B7: sum_i(B_i) / (P_a*b + s*q) | C7: Peak throughput: aggregate memory bandwidth divided by bytes read per token. Grows linearly with device count. Measured saturation reaches 0.86-0.98 of it depending on scale.
A8: X(G) | B8: X_max * min(1, G/N) | C8: The utilisation ramp. Measured here to be an UPPER BOUND, not a predictor: it assumes a stream computes continuously, so its slack is the network's share of per-token time. 32% optimistic at container scale (21% network), 1-2% at report scale (1.6% network).
A9: closed-loop rate | B9: min( G/T_token , W/max_k(compute_k) ) | C9: Not in the research report; added here. The smaller of a delay bound and a capacity bound. Tracks measurement at 0.88 +/- 0.03 across a 32x range of G, where the ramp is 32% out.
A10: X_pipe | B10: 1 / max_k(t_k), t_k = (W_k*b + KV_k)/B_k + l | C10: A pipeline runs no faster than its slowest stage. This is where heterogeneity bites: equal sharding across tiers differing 100x in bandwidth lets the weakest node set the clock for everyone.
A11: stage availability | B11: 1 - (1-p)^W | C11: A stage is usable while any one of its W replicas is reachable. Measured as a cliff rather than a slope: at W=1 a single kill failed over a thousand requests and never recovered; at W=2, zero to three.
A12: KV working set | B12: 2*L*d*b_kv * s * G | C12: Scales with context length and concurrency, and competes with weights for the same scarce per-node memory. Not stressed by these experiments (short prompts), so no finding is offered on it.
A14: Symbols
A15: symbol | B15: units | C15: meaning
A16: N | B16: count | C16: Devices in the pool
A17: D, W | B17: count | C17: Pipeline depth (stages) and replica width; N = D x W
A18: B_i | B18: bytes/s | C18: Device i's memory bandwidth - the governing resource, because decode is memory-bound, not compute-bound
A19: P, P_a | B19: count | C19: Total and per-token active parameters (P_a much smaller than P for a sparse MoE)
A20: b | B20: bytes | C20: Bytes per parameter: 2 = FP16, 0.5 = INT4, 4 = FP32
A21: L, d | B21: count | C21: Model layers and hidden dimension
A22: s, q | B22: tokens, bytes | C22: Context length and KV bytes per cached token
A23: a | B23: bytes | C23: Activation payload crossing each hop, about 2*d*b
A24: l, beta | B24: seconds, bytes/s | C24: Per-hop link latency and link bandwidth
A25: G | B25: count | C25: Concurrent independent token streams in flight
A26: p_i | B26: fraction | C26: Device availability: fraction of time reachable
A27: t_k | B27: seconds | C27: Service time of stage k for one token
A29: Model profiles
A30: profile | B30: total params P | C30: active params P_a | D30: bytes/param b | E30: layers L | F30: hidden d | G30: P_a*b (GB) | H30: notes
A31: report_moe | B31: 1e12 | C31: 60e9 | D31: 0.5 | E31: 80 | F31: 8192 | G31: 30 | H31: The research report's appendix model: a 1T-parameter sparse MoE at INT4. Used for the report-scale virtual runs.
A32: poc_small | B32: 50e9 | C32: 5.4e9 | D32: 0.5 | E32: 24 | F32: 2048 | G32: 2.7 | H32: Scaled so synthetic stage times land in the tens of milliseconds, the same order as the emulated hop delays (1-50 ms). The report's own model would give about 3 s per stage, making every container run network-trivial and absurdly slow to gather data from.
A33: qwen_0_5b | B33: 494e6 | C33: 358e6 | D33: 4 | E33: 24 | F33: 896 | G33: 1.432 | H33: Qwen2.5-0.5B-Instruct, used in real mode. active_params counts the 24 decoder layers only: the 136M tied embedding/output matrix sits on the gateway, not on a stage worker. Verified against the downloaded weights (1.432 GB in layers, 544 MB outside).
A35: Device tiers (emulated)
A36: tier | B36: stands for | C36: B (GB/s) | D36: availability p | E36: CPU cores | F36: memory (MB) | G36: link (Mbit/s) | H36: delay (ms)
A37: 3 | B37: Gaming PC (GPU) | C37: 600 | D37: 0.97 | E37: 2 | F37: 4096 | G37: 1000 | H37: 1
A38: 2 | B38: Laptop / idle desktop (CPU) | C38: 45 | D38: 0.9 | E38: 1 | F38: 2048 | G38: 500 | H38: 5
A39: 1 | B39: Single-board computer (Pi-class) | C39: 10 | D39: 0.75 | E39: 0.5 | F39: 1024 | G39: 100 | H39: 10
A40: 0 | B40: Microcontroller / IoT node | C40: 3 | D40: 0.4 | E40: 0.1 | F40: 256 | G40: 10 | H40: 50
A42: - Memory bandwidth and availability drive the cost model; the CPU, memory, link and delay columns are the single-host container emulation. These preserve the tiers' RATIOS, not absolute device speeds. Experiment 7 measures a tier-2 container's real effective bandwidth as 6.9 GB/s against the 45 GB/s nominal - 6.5x slower, and closer to the tier-1 reference than to the tier-2 one it was configured as. Availability and churn session lengths are this harness's own defaults: the research report gives them only qualitatively ("low, bursty" to "high").

Sheet Provenance & limits
A1: Provenance, method, and the limits on these numbers
A2: Taken from the run manifests.
A4: area | B4: item | C4: value
A5: Harness | B5: repository | C5: https://github.com/JohnBullDog/swarm-poc-network-fault-harness
A6: Harness | B6: git commit at run time | C6: (uncommitted at run time)
A7: Harness | B7: container image (synthetic) | C7: n/a
A8: Harness | B8: run manifests | C8: Each run directory under runs/ carries a full manifest: resolved scenario, placement, predictions, fault schedule, suppressed faults, and host facts.
A9: Host | B9: platform | C9: Windows-11-10.0.26200-SP0
A10: Host | B10: python | C10: 3.12.10
A11: Host | B11: docker
A12: Host | B12: docker CPUs
A13: Host | B13: docker memory (bytes)
A14: Host | B14: kernel | C14: WSL2 6.18; sch_netem, sch_tbf and sch_htb verified present and working inside containers before anything was built on them
A15: Host | B15: RAM | C15: 16 GB total; WSL2 ceiling raised from 8 GB to 11 GB
A16: Method | B16: run ordering | C16: Sequential. Two concurrent runs would each measure the other's CPU and memory-bandwidth interference.
A17: Method | B17: clock | C17: All containers share the host's CLOCK_REALTIME and are given one RUN_EPOCH, so one-way hop times are measured directly with no clock synchronisation.
A18: Method | B18: network shaping | C18: tc netem (delay, jitter, loss) nested under tbf (rate cap), applied by each container to its own egress at startup. netem shapes EGRESS, so a hop A->B costs A's configured delay.
A19: Method | B19: activation flow | C19: Forward-only: gateway -> s0 -> ... -> s(D-1) -> gateway, giving D+1 hops. An earlier nested-HTTP version charged 2D hop delays, which would have doubled the delay sweep's slope.
A20: Method | B20: real model | C20: Qwen2.5-0.5B-Instruct, fetched once and bind-mounted read-only, greedy decoding so runs are reproducible and output is checkable.
A21: Method | B21: steady state | C21: Statistics exclude a warm-up interval and, where noted, fault windows. Nothing is deleted: rows carry in_steady_state and fault_window labels.
A23: Limits - these bound what any number here can mean
A24: - ONE HOST. Every container shares its CPU and memory bandwidth. The cgroup limits reduce but do not eliminate the interference.
A25: - TIERS PRESERVE RATIOS, NOT ABSOLUTE SPEEDS. Nothing here says what a Raspberry Pi would actually do. Experiment 7 measures the gap for tier 2 as 6.5x.
A26: - SYNTHETIC MODE MODELS NEITHER CPU CONTENTION NOR PREFILL COST. It over-predicts throughput by 1.6-2.2x even after bandwidth calibration, and its latency error grows with concurrency: 3.9% at G=1, 31% at G=4. Synthetic results speak to network and churn effects, not to a real deployment's absolute throughput.
A27: - VIRTUAL-ENGINE RESULTS are valid for per-token latency, stage compute, network time and AGGREGATE queueing (agreeing with containers to a few per cent) and over-predict throughput by 6-8%. They are NOT valid for queue-wait distribution or tail latency: deterministic service concentrates all waiting in a third of hops where real jitter smears it.
A28: - PREDICTIONS CARRY NO FITTED CORRECTION. The measured/predicted ratio is the harness's own cost, reported rather than subtracted out. An earlier fitted correction was removed after it proved circular and then load-dependent.
A29: - tc IS NOT A HOME NETWORK. It models delay and loss well, not the full behaviour of real links. The virtual engine's loss model charges one round trip per lost segment, which is TCP's best case, so its loss results are a lower bound on the real penalty.
A30: - NO INTEGRITY, SECURITY OR TRUST MODELLING. All containers are trusted. The research report's verification questions are explicitly out of scope for this harness.

Sheet exp1 Concurrency
A1: Experiment 1 - Concurrency sweep
A2: D=3, W=2, N=6 tier-2 nodes, poc_small, no churn. Blue = measured or predicted from the dataset; black = computed in-sheet.
A4: concurrency_G | B4: n_nodes_N | C4: meas_throughput_tok_s | D4: pred_x_of_g_tok_s | E4: pred_x_delay_bound_tok_s | F4: pred_x_capacity_compute_tok_s | G4: pred_x_closed_loop_tok_s | H4: meas_t_token_s_p50 | I4: meas_t_token_s_p95 | J4: pred_t_token_s | K4: mean_busy_frac | L4: requests_ok | M4: requests_failed | N4: run_id | O4: X / ramp | P4: X / closed-loop | Q4: p50 (ms)
A5: 1 | B5: 6 | C5: 11.228493 | D5: 16.647271 | E5: 13.126014 | F5: 99.883627 | G5: 13.126014 | H5: 0.084524155 | I5: 0.087335992 | J5: 0.076184593 | K5: 0.11610047 | L5: 88 | M5: 0 | N5: exp1_concurrency_g01-20261029T191409Z | O5: =C5/D5 -> 0.67449453 | P5: =C5/G5 -> 0.8554382 | Q5: =H5*1000 -> 84.524155
A6: 2 | B6: 6 | C6: 22.564703 | D6: 33.294542 | E6: 26.252027 | F6: 99.883627 | G6: 26.252027 | H6: 0.084240675 | I6: 0.087430215 | J6: 0.076184593 | K6: 0.23439478 | L6: 176 | M6: 0 | N6: exp1_concurrency_g02-20261029T191523Z | O6: =C6/D6 -> 0.6777298 | P6: =C6/G6 -> 0.85954138 | Q6: =H6*1000 -> 84.240675
A7: 3 | B7: 6 | C7: 33.759524 | D7: 49.941814 | E7: 39.378041 | F7: 99.883627 | G7: 39.378041 | H7: 0.084113836 | I7: 0.089408958 | J7: 0.076184593 | K7: 0.35081209 | L7: 264 | M7: 0 | N7: exp1_concurrency_g03-20261029T191637Z | O7: =C7/D7 -> 0.67597714 | P7: =C7/G7 -> 0.85731854 | Q7: =H7*1000 -> 84.113836
A8: 4 | B8: 6 | C8: 44.944281 | D8: 66.589085 | E8: 52.504054 | F8: 99.883627 | G8: 52.504054 | H8: 0.084147215 | I8: 0.091146374 | J8: 0.076184593 | K8: 0.46887612 | L8: 352 | M8: 0 | N8: exp1_concurrency_g04-20261029T191751Z | O8: =C8/D8 -> 0.67494967 | P8: =C8/G8 -> 0.85601544 | Q8: =H8*1000 -> 84.147215
A9: 6 | B9: 6 | C9: 67.817708 | D9: 99.883627 | E9: 78.756081 | F9: 99.883627 | G9: 78.756081 | H9: 0.083893299 | I9: 0.088438845 | J9: 0.076184593 | K9: 0.700021 | L9: 528 | M9: 0 | N9: exp1_concurrency_g06-20261029T191904Z | O9: =C9/D9 -> 0.67896722 | P9: =C9/G9 -> 0.86111075 | Q9: =H9*1000 -> 83.893299
A10: 8 | B10: 6 | C10: 88.869581 | D10: 99.883627 | E10: 105.00811 | F10: 99.883627 | G10: 99.883627 | H10: 0.085001111 | I10: 0.091685224 | J10: 0.076184593 | K10: 0.91141507 | L10: 694 | M10: 0 | N10: exp1_concurrency_g08-20261029T192019Z | O10: =C10/D10 -> 0.88973122 | P10: =C10/G10 -> 0.88973122 | Q10: =H10*1000 -> 85.001111
A11: 12 | B11: 6 | C11: 89.546012 | D11: 99.883627 | E11: 157.51216 | F11: 99.883627 | G11: 99.883627 | H11: 0.12789011 | I11: 0.13188651 | J11: 0.076184593 | K11: 0.91550242 | L11: 696 | M11: 0 | N11: exp1_concurrency_g12-20261029T192134Z | O11: =C11/D11 -> 0.89650341 | P11: =C11/G11 -> 0.89650341 | Q11: =H11*1000 -> 127.89011
A12: 16 | B12: 6 | C12: 92.212801 | D12: 99.883627 | E12: 210.01622 | F12: 99.883627 | G12: 99.883627 | H12: 0.16959667 | I12: 0.17353384 | J12: 0.076184593 | K12: 0.93289501 | L12: 704 | M12: 0 | N12: exp1_concurrency_g16-20261029T192249Z | O12: =C12/D12 -> 0.92320237 | P12: =C12/G12 -> 0.92320237 | Q12: =H12*1000 -> 169.59667
A13: 24 | B13: 6 | C13: 89.876374 | D13: 99.883627 | E13: 315.02432 | F13: 99.883627 | G13: 99.883627 | H13: 0.25527906 | I13: 0.25910437 | J13: 0.076184593 | K13: 0.92551232 | L13: 696 | M13: 0 | N13: exp1_concurrency_g24-20261029T192403Z | O13: =C13/D13 -> 0.89981088 | P13: =C13/G13 -> 0.89981088 | Q13: =H13*1000 -> 255.27906
A14: 32 | B14: 6 | C14: 90.157296 | D14: 99.883627 | E14: 420.03243 | F14: 99.883627 | G14: 99.883627 | H14: 0.33914065 | I14: 0.34384387 | J14: 0.076184593 | K14: 0.93330344 | L14: 704 | M14: 0 | N14: exp1_concurrency_g32-20261029T192519Z | O14: =C14/D14 -> 0.90262336 | P14: =C14/G14 -> 0.90262336 | Q14: =H14*1000 -> 339.14065

Sheet exp2 Delay
A1: Experiment 2 - Delay sweep
A2: W=1, G=1 so no queueing confounds the hop term. The slope of latency against per-hop delay should equal D: only the tier-2 link is swept, and tier-2 nodes send D of the path's D+1 hops.
A4: depth_D | B4: sweep_delay_ms | C4: meas_t_token_s_p50 | D4: pred_t_token_s | E4: pred_t_token_s_report | F4: meas_throughput_tok_s | G4: latency_ratio_p50_over_pred | H4: tokens_steady | I4: run_id | J4: p50 (ms)
A5: 2 | B5: 1 | C5: 0.069268227 | D5: 0.063151825 | E5: 0.062135441 | F5: 13.836299 | G5: 1.0968523 | H5: 571 | I5: exp2_delay_d2_l01ms-20261029T192644Z | J5: =C5*1000 -> 69.268227
A6: 2 | B6: 5 | C6: 0.077233791 | D6: 0.071151825 | E6: 0.070135441 | F6: 12.381958 | G6: 1.0854787 | H6: 512 | I6: exp2_delay_d2_l05ms-20261029T192740Z | J6: =C6*1000 -> 77.233791
A7: 2 | B7: 25 | C7: 0.11724663 | D7: 0.11115183 | E7: 0.11013544 | F7: 8.1968213 | G7: 1.0548331 | H7: 339 | I7: exp2_delay_d2_l25ms-20261029T192837Z | J7: =C7*1000 -> 117.24663
A8: 2 | B8: 50 | C8: 0.16732049 | D8: 0.16115183 | E8: 0.16013544 | F8: 5.6160938 | G8: 1.0382786 | H8: 239 | I8: exp2_delay_d2_l50ms-20261029T192933Z | J8: =C8*1000 -> 167.32049
A9: 3 | B9: 1 | C9: 0.07255888 | D9: 0.064184593 | E9: 0.063168209 | F9: 12.807065 | G9: 1.1304719 | H9: 545 | I9: exp2_delay_d3_l01ms-20261029T193028Z | J9: =C9*1000 -> 72.55888
A10: 3 | B10: 5 | C10: 0.084547043 | D10: 0.076184593 | E10: 0.075168209 | F10: 11.404676 | G10: 1.1097656 | H10: 471 | I10: exp2_delay_d3_l05ms-20261029T193126Z | J10: =C10*1000 -> 84.547043
A11: 3 | B11: 25 | C11: 0.14468408 | D11: 0.13618459 | E11: 0.13516821 | F11: 6.6925288 | G11: 1.0624115 | H11: 277 | I11: exp2_delay_d3_l25ms-20261029T193222Z | J11: =C11*1000 -> 144.68408
A12: 3 | B12: 50 | C12: 0.219733 | D12: 0.21118459 | E12: 0.21016821 | F12: 4.4129963 | G12: 1.0404784 | H12: 182 | I12: exp2_delay_d3_l50ms-20261029T193319Z | J12: =C12*1000 -> 219.733
A13: 4 | B13: 1 | C13: 0.07541585 | D13: 0.065217361 | E13: 0.064200977 | F13: 12.717202 | G13: 1.1563769 | H13: 541 | I13: exp2_delay_d4_l01ms-20261029T193416Z | J13: =C13*1000 -> 75.41585
A14: 4 | B14: 5 | C14: 0.090736866 | D14: 0.081217361 | E14: 0.080200977 | F14: 10.317189 | G14: 1.1172102 | H14: 439 | I14: exp2_delay_d4_l05ms-20261029T193512Z | J14: =C14*1000 -> 90.736866
A15: 4 | B15: 25 | C15: 0.17083573 | D15: 0.16121736 | E15: 0.16020098 | F15: 5.510645 | G15: 1.0596609 | H15: 235 | I15: exp2_delay_d4_l25ms-20261029T193609Z | J15: =C15*1000 -> 170.83573
A16: 4 | B16: 50 | C16: 0.27080488 | D16: 0.26121736 | E16: 0.26020098 | F16: 3.5987582 | G16: 1.0367032 | H16: 149 | I16: exp2_delay_d4_l50ms-20261029T193705Z | J16: =C16*1000 -> 270.80488
... A20: 6 | B20: 50 | C20: 0.37147856 | D20: 0.3612829 | E20: 0.36026651 | F20: 2.5351176 | G20: 1.0282207 | H20: 108 | I20: exp2_delay_d6_l50ms-20261029T194056Z | J20: =C20*1000 -> 371.47856
A23: Measured slope per depth (SLOPE of p50 in ms against delay in ms)
A24: depth D | B24: rows | C24: measured slope | D24: predicted slope (= D) | E24: error % | F24: |error| % | G24: R2
A25: 2 | B25: 5:8 | C25: =SLOPE(J5:J8,B5:B8) -> 2.0013089 | D25: =A25 -> 2 | E25: =(C25-D25)/D25 -> 0.00065443505 | F25: =ABS(E25) -> 0.00065443505 | G25: =RSQ(J5:J8,B5:B8) -> 0.9999997
A26: 3 | B26: 9:12 | C26: =SLOPE(J9:J12,B9:B12) -> 3.0039419 | D26: =A26 -> 3 | E26: =(C26-D26)/D26 -> 0.0013139756 | F26: =ABS(E26) -> 0.0013139756 | G26: =RSQ(J9:J12,B9:B12) -> 0.99999985
A27: 4 | B27: 13:16 | C27: =SLOPE(J13:J16,B13:B16) -> 3.9929986 | D27: =A27 -> 4 | E27: =(C27-D27)/D27 -> -0.0017503456 | F27: =ABS(E27) -> 0.0017503456 | G27: =RSQ(J13:J16,B13:B16) -> 0.99999076
A28: 6 | B28: 17:20 | C28: =SLOPE(J17:J20,B17:B20) -> 6.0113318 | D28: =A28 -> 6 | E28: =(C28-D28)/D28 -> 0.001888625 | F28: =ABS(E28) -> 0.001888625 | G28: =RSQ(J17:J20,B17:B20) -> 0.99999812

Sheet exp4 Failover
A1: Experiment 4 - Disconnection and failover
A2: One kill of a middle-stage replica at t=20 s. death_after = 4 x heartbeat. Arm W_x_heartbeat varies replica count and heartbeat; arm hop_timeout varies the client timeout at W=2, heartbeat 500 ms. A blank recovery means the stage never recovered (W=1: no replica).
A4: sweep_arm | B4: width_W | C4: heartbeat_ms | D4: death_after_ms | E4: sweep_hop_timeout_ms | F4: concurrency_G | G4: requests_ok | H4: requests_failed | I4: retries_total | J4: detection_s_mean | K4: recovery_s_mean | L4: meas_throughput_tok_s | M4: run_id
A5: W_x_heartbeat | B5: 1 | C5: 250 | D5: 1000 | E5: 500 | F5: 6 | G5: 108 | H5: 1183 | I5: 7 | J5: 0.67995095 | L5: 42.945149 | M5: exp4_failover_w1_hb0250-20261029T194200Z
A6: W_x_heartbeat | B6: 1 | C6: 500 | D6: 2000 | E6: 500 | F6: 6 | G6: 108 | H6: 1155 | I6: 0 | J6: 1.3389103 | L6: 43.13578 | M6: exp4_failover_w1_hb0500-20261029T194303Z
A7: W_x_heartbeat | B7: 1 | C7: 1000 | D7: 4000 | E7: 500 | F7: 6 | G7: 108 | H7: 1081 | I7: 0 | J7: 3.2179189 | L7: 43.374328 | M7: exp4_failover_w1_hb1000-20261029T194404Z
A8: W_x_heartbeat | B8: 2 | C8: 250 | D8: 1000 | E8: 500 | F8: 6 | G8: 342 | H8: 0 | I8: 24 | J8: 0.69779086 | K8: 0.77799296 | L8: 50.533967 | M8: exp4_failover_w2_hb0250-20261029T194506Z
A9: W_x_heartbeat | B9: 2 | C9: 500 | D9: 2000 | E9: 500 | F9: 6 | G9: 339 | H9: 1 | I9: 15 | J9: 1.3194675 | K9: 1.3955455 | L9: 50.448397 | M9: exp4_failover_w2_hb0500-20261029T194610Z
A10: W_x_heartbeat | B10: 2 | C10: 1000 | D10: 4000 | E10: 500 | F10: 6 | G10: 329 | H10: 1 | I10: 37 | J10: 3.6546748 | K10: 3.6570249 | L10: 48.538037 | M10: exp4_failover_w2_hb1000-20261029T194714Z
A11: W_x_heartbeat | B11: 3 | C11: 250 | D11: 1000 | E11: 500 | F11: 6 | G11: 432 | H11: 0 | I11: 9 | J11: 0.48678398 | K11: 0.4986937 | L11: 67.748959 | M11: exp4_failover_w3_hb0250-20261029T194817Z
A12: W_x_heartbeat | B12: 3 | C12: 500 | D12: 2000 | E12: 500 | F12: 6 | G12: 425 | H12: 1 | I12: 13 | J12: 1.3712108 | K12: 1.4027455 | L12: 66.889216 | M12: exp4_failover_w3_hb0500-20261029T194922Z
A13: W_x_heartbeat | B13: 3 | C13: 1000 | D13: 4000 | E13: 500 | F13: 6 | G13: 411 | H13: 0 | I13: 36 | J13: 3.7315283 | K13: 3.751137 | L13: 64.213687 | M13: exp4_failover_w3_hb1000-20261029T195027Z
A14: hop_timeout | B14: 2 | C14: 500 | D14: 2000 | E14: 250 | F14: 6 | G14: 344 | H14: 2 | I14: 23 | J14: 1.4750519 | K14: 1.4923935 | L14: 52.286781 | M14: exp4_timeout_t0250-20261029T195132Z
A15: hop_timeout | B15: 2 | C15: 500 | D15: 2000 | E15: 1000 | F15: 6 | G15: 337 | H15: 0 | I15: 15 | J15: 1.4748719 | K15: 1.944124 | L15: 51.534524 | M15: exp4_timeout_t1000-20261029T195235Z
A16: hop_timeout | B16: 2 | C16: 500 | D16: 2000 | E16: 2000 | F16: 6 | G16: 337 | H16: 0 | I16: 8 | J16: 1.3291893 | K16: 1.8328507 | L16: 51.439964 | M16: exp4_timeout_t2000-20261029T195339Z
A17: hop_timeout | B17: 2 | C17: 500 | D17: 2000 | E17: 5000 | F17: 6 | G17: 328 | H17: 0 | I17: 9 | J17: 1.6424057 | K17: 3.9053695 | L17: 49.540553 | M17: exp4_timeout_t5000-20261029T195442Z

Sheet Recovery per fault
A1: Recovery - one row per injected fault
A2: detection_s: fault to the coordinator marking the node dead. recovery_s: fault to the first successful token routed around it AFTER detection. reroute_s: first token avoiding it at all, which under round-robin is near-instant and says little. stall_s: fault to the last error naming the node.
A4: run_id | B4: node_id | C4: tier | D4: stage | E4: action | F4: fault_sim_ts | G4: detected_sim_ts | H4: first_ok_sim_ts | I4: detection_s | J4: recovery_s | K4: reroute_s | L4: stall_s | M4: tokens_failed_between | N4: scheduled_at_s | O4: apply_ms
A5: exp4_failover_w1_hb0250-20261029T194200Z | B5: n-s1-r0 | C5: 2 | D5: 1 | E5: kill | F5: 24.490442 | G5: 25.170393 | I5: 0.67995095 | M5: 11
A6: exp4_failover_w1_hb0500-20261029T194303Z | B6: n-s1-r0 | C6: 2 | D6: 1 | E6: kill | F6: 23.963559 | G6: 25.302469 | I6: 1.3389103 | M6: 17
A7: exp4_failover_w1_hb1000-20261029T194404Z | B7: n-s1-r0 | C7: 2 | D7: 1 | E7: kill | F7: 24.560527 | G7: 27.778446 | I7: 3.2179189 | M7: 41
A8: exp4_failover_w2_hb0250-20261029T194506Z | B8: n-s1-r0 | C8: 2 | D8: 1 | E8: kill | F8: 24.837765 | G8: 25.535556 | H8: 25.615758 | I8: 0.69779086 | J8: 0.77799296 | K8: 0.041475534 | L8: 1.2517135 | M8: 5
A9: exp4_failover_w2_hb0500-20261029T194610Z | B9: n-s1-r0 | C9: 2 | D9: 1 | E9: kill | F9: 24.624963 | G9: 25.944431 | H9: 26.020509 | I9: 1.3194675 | J9: 1.3955455 | K9: 0.0029480457 | L9: 1.7829149 | M9: 10
A10: exp4_failover_w2_hb1000-20261029T194714Z | B10: n-s1-r0 | C10: 2 | D10: 1 | E10: kill | F10: 24.735205 | G10: 28.38988 | H10: 28.39223 | I10: 3.6546748 | J10: 3.6570249 | K10: 0.01159811 | L10: 3.8322735 | M10: 31
A11: exp4_failover_w3_hb0250-20261029T194817Z | B11: n-s1-r0 | C11: 2 | D11: 1 | E11: kill | F11: 25.485778 | G11: 25.972562 | H11: 25.984471 | I11: 0.48678398 | J11: 0.4986937 | K11: 0.00098156929 | L11: 0.95513535 | M11: 3
A12: exp4_failover_w3_hb0500-20261029T194922Z | B12: n-s1-r0 | C12: 2 | D12: 1 | E12: kill | F12: 24.802928 | G12: 26.174139 | H12: 26.205674 | I12: 1.3712108 | J12: 1.4027455 | K12: 0.0053818226 | L12: 1.825841 | M12: 10
A13: exp4_failover_w3_hb1000-20261029T195027Z | B13: n-s1-r0 | C13: 2 | D13: 1 | E13: kill | F13: 25.810653 | G13: 29.542182 | H13: 29.56179 | I13: 3.7315283 | J13: 3.751137 | K13: 0.014913559 | L13: 3.8319786 | M13: 29
A14: exp4_timeout_t0250-20261029T195132Z | B14: n-s1-r0 | C14: 2 | D14: 1 | E14: kill | F14: 25.457654 | G14: 26.932705 | H14: 26.950047 | I14: 1.4750519 | J14: 1.4923935 | K14: 0.010084152 | L14: 1.7666984 | M14: 21
A15: exp4_timeout_t1000-20261029T195235Z | B15: n-s1-r0 | C15: 2 | D15: 1 | E15: kill | F15: 25.425681 | G15: 26.900553 | H15: 27.369805 | I15: 1.4748719 | J15: 1.944124 | K15: 0.0043125153 | L15: 2.412564 | M15: 6
A16: exp4_timeout_t2000-20261029T195339Z | B16: n-s1-r0 | C16: 2 | D16: 1 | E16: kill | F16: 25.317436 | G16: 26.646625 | H16: 27.150287 | I16: 1.3291893 | J16: 1.8328507 | K16: 0.011049747 | L16: 2.1852 | M16: 1
A17: exp4_timeout_t5000-20261029T195442Z | B17: n-s1-r0 | C17: 2 | D17: 1 | E17: kill | F17: 25.324196 | G17: 26.966602 | H17: 29.229566 | I17: 1.6424057 | J17: 3.9053695 | K17: 0.0048353672 | L17: 3.7549675 | M17: 5

Sheet exp7 Mode check
A1: Experiment 7 - Mode check: does synthetic timing track real?
A2: Qwen2.5-0.5B split 8/8/8 layers over three tier-2 containers, CPU float32, greedy decoding. 'nominal' uses the tier-2 reference bandwidth of 45 GB/s; 'calibrated' uses B_eff fitted from the real runs. This experiment is what licenses every synthetic result.
A4: concurrency_G | B4: arm | C4: real_run | D4: synthetic_run | E4: real_p50_ms | F4: synthetic_p50_ms | G4: p50_rel_err | H4: real_throughput_tok_s | I4: synthetic_throughput_tok_s | J4: throughput_rel_err | K4: within_tolerance | L4: b_eff_gbs | M4: |p50 error|
A5: 1 | B5: synthetic_calibrated | C5: exp7_real_g1-20261029T233751Z | D5: exp7_synthetic_calibrated_g1-20261029T234552Z | E5: 241.83142 | F5: 232.39136 | G5: -0.039035723 | H5: 2.7215433 | I5: 4.2580742 | J5: 0.56458072 | K5: TRUE | L5: 6.8997309 | M5: =ABS(G5) -> 0.039035723
A6: 2 | B6: synthetic_calibrated | C6: exp7_real_g2-20261029T233956Z | D6: exp7_synthetic_calibrated_g2-20261029T234924Z | E6: 292.98353 | F6: 232.78332 | G6: -0.20547303 | H6: 4.721303 | I6: 8.4849156 | J6: 0.79715548 | K6: FALSE | L6: 6.8997309 | M6: =ABS(G6) -> 0.20547303
A7: 4 | B7: synthetic_calibrated | C7: exp7_real_g4-20261029T234200Z | D7: exp7_synthetic_calibrated_g4-20261029T235255Z | E7: 414.20627 | F7: 284.96909 | G7: -0.31201164 | H7: 6.2895328 | I7: 13.921972 | J7: 1.2135145 | K7: FALSE | L7: 6.8997309 | M7: =ABS(G7) -> 0.31201164
A8: 1 | B8: synthetic_nominal | C8: exp7_real_g1-20261029T233751Z | D8: exp7_synthetic_nominal_g1-20261029T234406Z | E8: 241.83142 | F8: 56.392193 | G8: -0.76681197 | H8: 2.7215433 | I8: 17.010548 | J8: 5.2503317 | K8: FALSE | L8: 6.8997309 | M8: =ABS(G8) -> 0.76681197
A9: 2 | B9: synthetic_nominal | C9: exp7_real_g2-20261029T233956Z | D9: exp7_synthetic_nominal_g2-20261029T234738Z | E9: 292.98353 | F9: 56.492686 | G9: -0.80718136 | H9: 4.721303 | I9: 34.340339 | J9: 6.2734875 | K9: FALSE | L9: 6.8997309 | M9: =ABS(G9) -> 0.80718136
A10: 4 | B10: synthetic_nominal | C10: exp7_real_g4-20261029T234200Z | D10: exp7_synthetic_nominal_g4-20261029T235109Z | E10: 414.20627 | F10: 59.240818 | G10: -0.85697749 | H10: 6.2895328 | I10: 63.850332 | J10: 9.1518401 | K10: FALSE | L10: 6.8997309 | M10: =ABS(G10) -> 0.85697749

Sheet exp1s Report scale
A1: Experiment 1s - Concurrency at report scale (virtual engine)
A2: Reconstruction of the research report's appendix example A: 1000 Pi-class nodes, 1T-param MoE at INT4 with 60B active, D=50, W=20. Virtual engine only - 1000 nodes is ~16x what this host runs as containers. Trustworthy only on the axes the engine comparison validates.
A4: concurrency_G | B4: n_nodes_N | C4: depth_D | D4: width_W | E4: meas_throughput_tok_s | F4: pred_x_of_g_tok_s | G4: pred_x_closed_loop_tok_s | H4: pred_x_max_tok_s | I4: meas_t_token_s_p50 | J4: pred_t_token_s | K4: throughput_efficiency | L4: tokens_steady | M4: run_id | N4: X / ramp
A5: 1 | B5: 1000 | C5: 50 | D5: 20 | E5: 0.33086669 | F5: 0.33333333 | G5: 0.32740272 | H5: 333.33333 | I5: 3.0545389 | J5: 3.0543423 | K5: 0.00099260006 | L5: 52 | M5: exp1s_scale_g0001-20261029T235751Z-virtual | N5: =E5/F5 -> 0.99260006
A6: 10 | B6: 1000 | C6: 50 | D6: 20 | E6: 3.3086669 | F6: 3.3333333 | G6: 3.2740272 | H6: 333.33333 | I6: 3.0545389 | J6: 3.0543423 | K6: 0.0099260006 | L6: 520 | M6: exp1s_scale_g0010-20261029T235757Z-virtual | N6: =E6/F6 -> 0.99260006
A7: 50 | B7: 1000 | C7: 50 | D7: 20 | E7: 16.530711 | F7: 16.666667 | G7: 16.370136 | H7: 333.33333 | I7: 3.0545389 | J7: 3.0543423 | K7: 0.049592133 | L7: 2600 | M7: exp1s_scale_g0050-20261029T235803Z-virtual | N7: =E7/F7 -> 0.99184265
A8: 100 | B8: 1000 | C8: 50 | D8: 20 | E8: 33.036213 | F8: 33.333333 | G8: 32.740272 | H8: 333.33333 | I8: 3.0545389 | J8: 3.0543423 | K8: 0.09910864 | L8: 5200 | M8: exp1s_scale_g0100-20261029T235814Z-virtual | N8: =E8/F8 -> 0.9910864
A9: 250 | B9: 1000 | C9: 50 | D9: 20 | E9: 82.339406 | F9: 83.333333 | G9: 81.850681 | H9: 333.33333 | I9: 3.0545389 | J9: 3.0543423 | K9: 0.24701822 | L9: 13000 | M9: exp1s_scale_g0250-20261029T235831Z-virtual | N9: =E9/F9 -> 0.98807288
A10: 500 | B10: 1000 | C10: 50 | D10: 20 | E10: 163.93113 | F10: 166.66667 | G10: 163.70136 | H10: 333.33333 | I10: 3.0545389 | J10: 3.0543423 | K10: 0.4917934 | L10: 26000 | M10: exp1s_scale_g0500-20261029T235906Z-virtual | N10: =E10/F10 -> 0.9835868
A11: 1000 | B11: 1000 | C11: 50 | D11: 20 | E11: 327.53405 | F11: 333.33333 | G11: 327.40272 | H11: 333.33333 | I11: 3.0544734 | J11: 3.0543423 | K11: 0.98260215 | L11: 52400 | M11: exp1s_scale_g1000-20261030T000013Z-virtual | N11: =E11/F11 -> 0.98260215
A12: 1500 | B12: 1000 | C12: 50 | D12: 20 | E12: 333.36225 | F12: 333.33333 | G12: 333.33333 | H12: 333.33333 | I12: 4.500291 | J12: 3.0543423 | K12: 1.0000868 | L12: 53320 | M12: exp1s_scale_g1500-20261030T000229Z-virtual | N12: =E12/F12 -> 1.0000868
A13: 2000 | B13: 1000 | C13: 50 | D13: 20 | E13: 333.36279 | F13: 333.33333 | G13: 333.33333 | H13: 333.33333 | I13: 6.0004037 | J13: 3.0543423 | K13: 1.0000884 | L13: 53320 | M13: exp1s_scale_g2000-20261030T000458Z-virtual | N13: =E13/F13 -> 1.0000884

Sheet Engine comparison
A1: Engine agreement - virtual against containers
A2: The harness's own measured overhead is fitted per configuration and given to the virtual engine, so what remains is attributable to the engines' models rather than to containerisation. Queue wait is compared as a MEAN: the distributions have the same mass but different shapes, so their medians legitimately differ.
A4: experiment | B4: scenario | C4: concurrency_G | D4: depth_D | E4: width_W | F4: container_run | G4: virtual_run | H4: tokens_container | I4: tokens_virtual | J4: fitted_stage_overhead_ms | K4: fitted_hop_overhead_ms | L4: stage_queue_median_ms_container | M4: stage_queue_median_ms_virtual | N4: t_token_p50_ms_container | O4: t_token_p50_ms_virtual | P4: t_token_p50_ms_rel_err | Q4: t_token_p50_ms_within_tol | R4: throughput_tok_s_container | S4: throughput_tok_s_virtual | T4: throughput_tok_s_rel_err | U4: throughput_tok_s_within_tol | V4: stage_compute_ms_container | W4: stage_compute_ms_virtual | X4: stage_compute_ms_rel_err | Y4: stage_compute_ms_within_tol | Z4: stage_net_ms_container | AA4: stage_net_ms_virtual | AB4: stage_net_ms_rel_err | AC4: stage_net_ms_within_tol | AD4: stage_queue_ms_container | AE4: stage_queue_ms_virtual | AF4: stage_queue_ms_rel_err | AG4: stage_queue_ms_within_tol
A5: exp1 | B5: exp1_concurrency_G01 | C5: 1 | D5: 3 | E5: 2 | F5: exp1_concurrency_g01-20261029T191409Z | G5: exp1_concurrency_g01-20261030T001155Z-cmp | H5: 647 | I5: 661 | J5: 1.2191977 | K5: 0.82553412 | L5: 0.17237663 | M5: 0 | N5: 84.524155 | O5: 83.153061 | P5: -0.016221328 | Q5: TRUE | R5: 11.228493 | S5: 12.028557 | T5: 0.071252954 | U5: TRUE | V5: 21.243334 | W5: 21.245412 | X5: 9.7830505e-05 | Y5: TRUE | Z5: 4.539043 | AA5: 4.5195074 | AB5: -0.0043038925 | AC5: TRUE | AD5: 0.18660019 | AE5: 0 | AF5: -1 | AG5: FALSE
A6: exp1 | B6: exp1_concurrency_G02 | C6: 2 | D6: 3 | E6: 2 | F6: exp1_concurrency_g02-20261029T191523Z | G6: exp1_concurrency_g02-20261030T001156Z-cmp | H6: 1299 | I6: 1326 | J6: 1.2083496 | K6: 0.78130747 | L6: 0.16641617 | M6: 0 | N6: 84.240675 | O6: 82.94361 | P6: -0.015397135 | Q6: TRUE | R6: 22.564703 | S6: 24.123379 | T6: 0.069075825 | U6: TRUE | V6: 21.23189 | W6: 21.234564 | X6: 0.00012595641 | Y6: TRUE | Z6: 4.6593119 | AA6: 4.4766277 | AB6: -0.039208416 | AC6: TRUE | AD6: 0.17848968 | AE6: 0 | AF6: -1 | AG6: FALSE
A7: exp1 | B7: exp1_concurrency_G03 | C7: 3 | D7: 3 | E7: 2 | F7: exp1_concurrency_g03-20261029T191637Z | G7: exp1_concurrency_g03-20261030T001157Z-cmp | H7: 1944 | I7: 1995 | J7: 1.1990513 | K7: 0.72498108 | L7: 0.15902519 | M7: 0 | N7: 84.113836 | O7: 82.690409 | P7: -0.016922625 | Q7: TRUE | R7: 33.759524 | S7: 36.291885 | T7: 0.07501175 | U7: TRUE | V7: 21.222591 | W7: 21.225266 | X7: 0.00012601159 | Y7: TRUE | Z7: 4.5531962 | AA7: 4.4198495 | AB7: -0.029286394 | AC7: TRUE | AD7: 0.21662314 | AE7: 0 | AF7: -1 | AG7: FALSE
A8: exp1 | B8: exp1_concurrency_G04 | C8: 4 | D8: 3 | E8: 2 | F8: exp1_concurrency_g04-20261029T191751Z | G8: exp1_concurrency_g04-20261030T001158Z-cmp | H8: 2589 | I8: 2662 | J8: 1.2023892 | K8: 0.70489432 | L8: 0.15926361 | M8: 0 | N8: 84.147215 | O8: 82.620076 | P8: -0.01814842 | Q8: TRUE | R8: 44.944281 | S8: 48.416401 | T8: 0.077253872 | U8: TRUE | V8: 21.225214 | W8: 21.228604 | X8: 0.00015969442 | Y8: TRUE | Z8: 4.5062072 | AA8: 4.3992029 | AB8: -0.023745998 | AC8: TRUE | AD8: 0.34452173 | AE8: 0 | AF8: -1 | AG8: FALSE
A9: exp1 | B9: exp1_concurrency_G06 | C9: 6 | D9: 3 | E9: 2 | F9: exp1_concurrency_g06-20261029T191904Z | G9: exp1_concurrency_g06-20261030T001200Z-cmp | H9: 3908 | I9: 4024 | J9: 1.043364 | K9: 0.67968155 | L9: 0.14853477 | M9: 0 | N9: 83.893299 | O9: 82.042149 | P9: -0.022065527 | Q9: TRUE | R9: 67.817708 | S9: 73.172859 | T9: 0.078963896 | U9: TRUE | V9: 21.11268 | W9: 21.069578 | X9: -0.0020415255 | Y9: TRUE | Z9: 4.5265773 | AA9: 4.3740988 | AB9: -0.033685164 | AC9: TRUE | AD9: 0.24158754 | AE9: 1.7669332e-15 | AF9: -1 | AG9: FALSE
A10: exp1 | B10: exp1_concurrency_G08 | C10: 8 | D10: 3 | E10: 2 | F10: exp1_concurrency_g08-20261029T192019Z | G10: exp1_concurrency_g08-20261030T001202Z-cmp | H10: 5120 | I10: 5278 | J10: 0.82151547 | K10: 0.64958121 | L10: 0.26154518 | M10: 0.0036408889 | N10: 85.001111 | O10: 83.389463 | P10: -0.018960316 | Q10: TRUE | R10: 88.869581 | S10: 95.969608 | T10: 0.079892658 | U10: TRUE | V10: 20.835161 | W10: 20.84773 | X10: 0.00060324292 | Y10: TRUE | Z10: 4.5364389 | AA10: 4.3435545 | AB10: -0.042518886 | AC10: TRUE | AD10: 0.90669042 | AE10: 0.711452 | AF10: -0.21533085 | AG10: TRUE
A11: exp1 | B11: exp1_concurrency_G12 | C11: 12 | D11: 3 | E11: 2 | F11: exp1_concurrency_g12-20261029T192134Z | G11: exp1_concurrency_g12-20261030T001205Z-cmp | H11: 5162 | I11: 5248 | J11: 0.9348239 | K11: 0.66144253 | L11: 15.412211 | M11: 0.0043690667 | N11: 127.89011 | O11: 125.76405 | P11: -0.016624153 | Q11: TRUE | R11: 89.546012 | S11: 95.440358 | T11: 0.065824764 | U11: TRUE | V11: 20.927668 | W11: 20.96031 | X11: 0.0015597776 | Y11: TRUE | Z11: 4.6148352 | AA11: 4.355586 | AB11: -0.056177355 | AC11: TRUE | AD11: 15.509506 | AE11: 14.705312 | AF11: -0.051851662 | AG11: TRUE
A12: exp1 | B12: exp1_concurrency_G16 | C12: 16 | D12: 3 | E12: 2 | F12: exp1_concurrency_g16-20261029T192249Z | G12: exp1_concurrency_g16-20261030T001208Z-cmp | H12: 5318 | I12: 5264 | J12: 0.86699382 | K12: 0.63885237 | L12: 22.252202 | M12: 0.0036408889 | N12: 169.59667 | O12: 167.14275 | P12: -0.014469146 | Q12: TRUE | R12: 92.212801 | S12: 95.741974 | T12: 0.038272044 | U12: TRUE | V12: 20.89262 | W12: 20.893208 | X12: 2.815013e-05 | Y12: TRUE | Z12: 4.5353212 | AA12: 4.3331649 | AB12: -0.044573768 | AC12: TRUE | AD12: 29.386712 | AE12: 28.590802 | AF12: -0.027084002 | AG12: TRUE
A13: exp1 | B13: exp1_concurrency_G24 | C13: 24 | D13: 3 | E13: 2 | F13: exp1_concurrency_g24-20261029T192403Z | G13: exp1_concurrency_g24-20261030T001211Z-cmp | H13: 5191 | I13: 5236 | J13: 0.98000422 | K13: 0.66722418 | L13: 22.259474 | M13: 0.0036408889 | N13: 255.27906 | O13: 252.07025 | P13: -0.012569812 | Q13: TRUE | R13: 89.876374 | S13: 95.216537 | T13: 0.059416756 | U13: TRUE | V13: 21.001101 | W13: 21.006219 | X13: 0.00024370546 | Y13: TRUE | Z13: 4.627606 | AA13: 4.3611975 | AB13: -0.057569388 | AC13: TRUE | AD13: 59.725826 | AE13: 56.756374 | AF13: -0.049718047 | AG13: TRUE
A14: exp1 | B14: exp1_concurrency_G32 | C14: 32 | D14: 3 | E14: 2 | F14: exp1_concurrency_g32-20261029T192519Z | G14: exp1_concurrency_g32-20261030T001214Z-cmp | H14: 5215 | I14: 5256 | J14: 0.89721337 | K14: 0.63754107 | L14: 21.779776 | M14: 0.0043690667 | N14: 339.14065 | O14: 334.76902 | P14: -0.012890329 | Q14: TRUE | R14: 90.157296 | S14: 95.5913 | T14: 0.06027249 | U14: TRUE | V14: 20.900011 | W14: 20.9227 | X14: 0.0010855751 | Y14: TRUE | Z14: 4.6914877 | AA14: 4.3315144 | AB14: -0.076729036 | AC14: TRUE | AD14: 89.133699 | AE14: 84.444961 | AF14: -0.052603427 | AG14: TRUE
A15: exp2 | B15: exp2_delay_D2_l01ms | C15: 1 | D15: 2 | E15: 1 | F15: exp2_delay_d2_l01ms-20261029T192644Z | G15: exp2_delay_d2_l01ms-20261030T001219Z-cmp | H15: 571 | I15: 587 | J15: 1.2212463 | K15: 0.83130766 | L15: 0.17094612 | M15: 0 | N15: 69.268227 | O15: 68.094794 | P15: -0.016940412 | Q15: TRUE | R15: 13.836299 | S15: 14.695843 | T15: 0.062122405 | U15: TRUE | V15: 31.256437 | W15: 31.259476 | X15: 9.7208181e-05 | Y15: TRUE | Z15: 1.8688089 | AA15: 1.8558837 | AB15: -0.0069162964 | AC15: TRUE | AD15: 0.18204032 | AE15: 0 | AF15: -1 | AG15: FALSE
A16: exp2 | B16: exp2_delay_D2_l05ms | C16: 1 | D16: 2 | E16: 1 | F16: exp2_delay_d2_l05ms-20261029T192740Z | G16: exp2_delay_d2_l05ms-20261030T001220Z-cmp | H16: 512 | I16: 526 | J16: 1.2099215 | K16: 0.84913756 | L16: 0.16880035 | M16: 0 | N16: 77.233791 | O16: 76.126727 | P16: -0.014333944 | Q16: TRUE | R16: 12.381958 | S16: 13.152996 | T16: 0.062271077 | U16: TRUE | V16: 31.246543 | W16: 31.249243 | X16: 8.6413931e-05 | Y16: TRUE | Z16: 3.87344 | AA16: 3.8756243 | AB16: 0.00056392469 | AC16: TRUE | AD16: 0.18044328 | AE16: 0 | AF16: -1 | AG16: FALSE
... A30: exp2 | B30: exp2_delay_D6_l50ms | C30: 1 | D30: 6 | E30: 1 | F30: exp2_delay_d6_l50ms-20261029T194056Z | G30: exp2_delay_d6_l50ms-20261030T001227Z-cmp | H30: 108 | I30: 109 | J30: 0.23045369 | K30: 0.87353254 | L30: 0.18644333 | M30: 0 | N30: 371.47856 | O30: 368.78909 | P30: -0.0072399131 | Q30: TRUE | R30: 2.5351176 | S30: 2.7255368 | T30: 0.075112567 | U30: TRUE | V30: 10.242462 | W30: 10.243561 | X30: 0.00010727183 | Y30: TRUE | Z30: 46.625837 | AA30: 42.76204 | AB30: -0.082868166 | AC30: TRUE | AD30: 0.20351808 | AE30: 0 | AF30: -1 | AG30: FALSE

Sheet All runs
A1: All runs - every experiment, every column
A2: One row per run, keyed by run_id. Every event table in datasets/ joins to this on run_id. Blank cells are columns that do not apply to that experiment (per-stage groups depend on depth; sweep_* on the axis varied).
A4: experiment | B4: scenario | C4: run_id | D4: engine | E4: mode | F4: depth_D | G4: width_W | H4: n_nodes_N | I4: concurrency_G | J4: placement | K4: model_profile | L4: duration_s | M4: tokens_steady | N4: pred_t_token_s_report | O4: pred_t_token_s | P4: pred_x_max_tok_s | Q4: pred_x_of_g_tok_s | R4: pred_x_delay_bound_tok_s | S4: pred_x_capacity_compute_tok_s | T4: pred_x_closed_loop_tok_s | U4: meas_throughput_tok_s | V4: meas_t_token_s_p50 | W4: meas_t_token_s_p95 | X4: meas_t_token_s_mean | Y4: mean_busy_frac | Z4: requests_ok | AA4: requests_failed | AB4: retries_total | AC4: failovers_total | AD4: throughput_efficiency | AE4: latency_ratio_p50_over_pred | AF4: image_id | AG4: seed | AH4: prompt_tokens | AI4: gen_tokens | AJ4: warmup_s | AK4: heartbeat_ms | AL4: death_after_ms | AM4: churn_kind | AN4: n_faults | AO4: n_departures | AP4: pred_x_pipe_tok_s | AQ4: pred_x_capacity_tok_s | AR4: pred_entry_hop_s | AS4: pred_slowest_stage | AT4: steady_lo_s | AU4: steady_hi_s | AV4: steady_window_s | AW4: tokens_total | AX4: meas_t_token_s_p99 | AY4: requests_started | AZ4: hop_errors | BA4: detection_s_mean | BB4: recovery_s_mean | BC4: latency_ratio_meas_over_pred | BD4: tokens_clean | BE4: fault_window_s | BF4: meas_throughput_tok_s_nofault | BG4: meas_t_token_s_p50_nofault | BH4: meas_t_token_s_mean_nofault | BI4: stalled_tokens | BJ4: n_tier2 | BK4: stage0_compute_s_mean | BL4: stage0_queue_wait_s_mean | BM4: stage0_net_s_mean | BN4: stage0_hops | BO4: stage1_compute_s_mean | BP4: stage1_queue_wait_s_mean | BQ4: stage1_net_s_mean | BR4: stage1_hops | BS4: stage2_compute_s_mean | BT4: stage2_queue_wait_s_mean | BU4: stage2_net_s_mean | BV4: stage2_hops | BW4: stage3_compute_s_mean | BX4: stage3_queue_wait_s_mean | BY4: stage3_net_s_mean | BZ4: stage3_hops | CA4: sweep_concurrency_G | CB4: sweep_hop_timeout_ms | CC4: sweep_depth_D | CD4: sweep_delay_ms | CE4: stage4_compute_s_mean | CF4: stage4_queue_wait_s_mean | CG4: stage4_net_s_mean | CH4: stage4_hops | CI4: stage5_compute_s_mean | CJ4: stage5_queue_wait_s_mean | CK4: stage5_net_s_mean | CL4: stage5_hops | CM4: stage6_compute_s_mean | CN4: stage6_queue_wait_s_mean | CO4: stage6_net_s_mean | CP4: stage6_hops | CQ4: sweep_width_W | CR4: sweep_heartbeat_ms | CS4: sweep_arm | CT4: n_tier1 | CU4: sweep_n_nodes
A5: 1_concurrency | B5: exp1_concurrency_G01 | C5: exp1_concurrency_g01-20261029T191409Z | D5: container | E5: synthetic | F5: 3 | G5: 2 | H5: 6 | I5: 1 | J5: capability_proportional | K5: poc_small | L5: 60 | M5: 647 | N5: 0.075168209 | O5: 0.076184593 | P5: 99.883627 | Q5: 16.647271 | R5: 13.126014 | S5: 99.883627 | T5: 13.126014 | U5: 11.228493 | V5: 0.084524155 | W5: 0.087335992 | X5: 0.088675503 | Y5: 0.11610047 | Z5: 88 | AA5: 0 | AB5: 0 | AC5: 0 | AD5: 0.11241575 | AE5: 1.1094652 | AF5: sha256:01857acd68d2 | AG5: 42 | AH5: 32 | AI5: 8 | AJ5: 5 | AK5: 500 | AL5: 2000 | AM5: none | AN5: 0 | AO5: 0 | AP5: 39.910489 | AQ5: 79.820979 | AR5: 0.001016384 | AS5: 0 | AT5: 9.7969394 | AU5: 67.418205 | AV5: 57.621266 | AW5: 704 | AX5: 0.096992521 | AY5: 88 | AZ5: 0 | BC5: 1.1639558 | BD5: 647 | BE5: 0 | BF5: 11.228493 | BG5: 0.084524155 | BH5: 0.088675503 | BI5: 4 | BJ5: 6 | BK5: 0.022182279 | BL5: 0.00018410005 | BM5: 0.0018479249 | BN5: 647 | BO5: 0.021150941 | BP5: 0.00018887652 | BQ5: 0.0058861494 | BR5: 647 | BS5: 0.022115299 | BT5: 0.00018682399 | BU5: 0.0058830547 | BV5: 647 | BW5: 0 | BX5: 0 | BY5: 0.0069061339 | BZ5: 647 | CA5: 1 | CB5: 2000
A6: 1_concurrency | B6: exp1_concurrency_G02 | C6: exp1_concurrency_g02-20261029T191523Z | D6: container | E6: synthetic | F6: 3 | G6: 2 | H6: 6 | I6: 2 | J6: capability_proportional | K6: poc_small | L6: 60 | M6: 1299 | N6: 0.075168209 | O6: 0.076184593 | P6: 99.883627 | Q6: 33.294542 | R6: 26.252027 | S6: 99.883627 | T6: 26.252027 | U6: 22.564703 | V6: 0.084240675 | W6: 0.087430215 | X6: 0.088348646 | Y6: 0.23439478 | Z6: 176 | AA6: 0 | AB6: 0 | AC6: 0 | AD6: 0.22590993 | AE6: 1.1057442 | AF6: sha256:01857acd68d2 | AG6: 42 | AH6: 32 | AI6: 8 | AJ6: 5 | AK6: 500 | AL6: 2000 | AM6: none | AN6: 0 | AO6: 0 | AP6: 39.910489 | AQ6: 79.820979 | AR6: 0.001016384 | AS6: 0 | AT6: 9.1690311 | AU6: 66.736816 | AV6: 57.567785 | AW6: 1414 | AX6: 0.090937281 | AY6: 178 | AZ6: 0 | BC6: 1.1596655 | BD6: 1299 | BE6: 0 | BF6: 22.564703 | BG6: 0.084240675 | BH6: 0.088348646 | BI6: 8 | BJ6: 6 | BK6: 0.023619776 | BL6: 0.00017370318 | BM6: 0.0023104086 | BN6: 1298 | BO6: 0.021159733 | BP6: 0.00017795522 | BQ6: 0.0058269436 | BR6: 1298 | BS6: 0.021619308 | BT6: 0.00018381062 | BU6: 0.0058405835 | BV6: 1298 | BW6: 0 | BX6: 0 | BY6: 0.0064449692 | BZ6: 1299 | CA6: 2 | CB6: 2000
A7: 1_concurrency | B7: exp1_concurrency_G03 | C7: exp1_concurrency_g03-20261029T191637Z | D7: container | E7: synthetic | F7: 3 | G7: 2 | H7: 6 | I7: 3 | J7: capability_proportional | K7: poc_small | L7: 60 | M7: 1944 | N7: 0.075168209 | O7: 0.076184593 | P7: 99.883627 | Q7: 49.941814 | R7: 39.378041 | S7: 99.883627 | T7: 39.378041 | U7: 33.759524 | V7: 0.084113836 | W7: 0.089408958 | X7: 0.088637427 | Y7: 0.35081209 | Z7: 264 | AA7: 0 | AB7: 0 | AC7: 0 | AD7: 0.33798857 | AE7: 1.1040794 | AF7: sha256:01857acd68d2 | AG7: 42 | AH7: 32 | AI7: 8 | AJ7: 5 | AK7: 500 | AL7: 2000 | AM7: none | AN7: 0 | AO7: 0 | AP7: 39.910489 | AQ7: 79.820979 | AR7: 0.001016384 | AS7: 0 | AT7: 9.832746 | AU7: 67.416496 | AV7: 57.58375 | AW7: 2115 | AX7: 0.092994757 | AY7: 267 | AZ7: 0 | BC7: 1.1634561 | BD7: 1944 | BE7: 0 | BF7: 33.759524 | BG7: 0.084113836 | BH7: 0.088637427 | BI7: 12 | BJ7: 6 | BK7: 0.021767036 | BL7: 0.00025323677 | BM7: 0.001759009 | BN7: 1941 | BO7: 0.023105685 | BP7: 0.00020458487 | BQ7: 0.0057916064 | BR7: 1942 | BS7: 0.021780031 | BT7: 0.00019209191 | BU7: 0.0061059351 | BV7: 1944 | BW7: 0 | BX7: 0 | BY7: 0.0062098303 | BZ7: 1944 | CA7: 3 | CB7: 2000
A8: 1_concurrency | B8: exp1_concurrency_G04 | C8: exp1_concurrency_g04-20261029T191751Z | D8: container | E8: synthetic | F8: 3 | G8: 2 | H8: 6 | I8: 4 | J8: capability_proportional | K8: poc_small | L8: 60 | M8: 2589 | N8: 0.075168209 | O8: 0.076184593 | P8: 99.883627 | Q8: 66.589085 | R8: 52.504054 | S8: 99.883627 | T8: 52.504054 | U8: 44.944281 | V8: 0.084147215 | W8: 0.091146374 | X8: 0.088740095 | Y8: 0.46887612 | Z8: 352 | AA8: 0 | AB8: 0 | AC8: 0 | AD8: 0.44996645 | AE8: 1.1045175 | AF8: sha256:01857acd68d2 | AG8: 42 | AH8: 32 | AI8: 8 | AJ8: 5 | AK8: 500 | AL8: 2000 | AM8: none | AN8: 0 | AO8: 0 | AP8: 39.910489 | AQ8: 79.820979 | AR8: 0.001016384 | AS8: 0 | AT8: 9.4292037 | AU8: 67.033863 | AV8: 57.604659 | AW8: 2817 | AX8: 0.095674658 | AY8: 353 | AZ8: 0 | BC8: 1.1648037 | BD8: 2589 | BE8: 0 | BF8: 44.944281 | BG8: 0.084147215 | BH8: 0.088740095 | BI8: 16 | BJ8: 6 | BK8: 0.023022913 | BL8: 0.00033343092 | BM8: 0.0017297448 | BN8: 2585 | BO8: 0.022610969 | BP8: 0.00046233289 | BQ8: 0.0060050431 | BR8: 2587 | BS8: 0.021155288 | BT8: 0.00023787525 | BU8: 0.005780702 | BV8: 2589 | BW8: 0 | BX8: 0 | BY8: 0.0059627435 | BZ8: 2589 | CA8: 4 | CB8: 2000
A9: 1_concurrency | B9: exp1_concurrency_G06 | C9: exp1_concurrency_g06-20261029T191904Z | D9: container | E9: synthetic | F9: 3 | G9: 2 | H9: 6 | I9: 6 | J9: capability_proportional | K9: poc_small | L9: 60 | M9: 3908 | N9: 0.075168209 | O9: 0.076184593 | P9: 99.883627 | Q9: 99.883627 | R9: 78.756081 | S9: 99.883627 | T9: 78.756081 | U9: 67.817708 | V9: 0.083893299 | W9: 0.088438845 | X9: 0.088200871 | Y9: 0.700021 | Z9: 528 | AA9: 0 | AB9: 0 | AC9: 0 | AD9: 0.67896722 | AE9: 1.1011846 | AF9: sha256:01857acd68d2 | AG9: 42 | AH9: 32 | AI9: 8 | AJ9: 5 | AK9: 500 | AL9: 2000 | AM9: none | AN9: 0 | AO9: 0 | AP9: 39.910489 | AQ9: 79.820979 | AR9: 0.001016384 | AS9: 0 | AT9: 9.3994679 | AU9: 67.024535 | AV9: 57.625067 | AW9: 4254 | AX9: 0.091762068 | AY9: 534 | AZ9: 0 | BC9: 1.1577258 | BD9: 3908 | BE9: 0 | BF9: 67.817708 | BG9: 0.083893299 | BH9: 0.088200871 | BI9: 24 | BJ9: 6 | BK9: 0.022147341 | BL9: 0.00028297452 | BM9: 0.0018554656 | BN9: 3905 | BO9: 0.022123786 | BP9: 0.00022902076 | BQ9: 0.0057767586 | BR9: 3906 | BS9: 0.02220607 | BT9: 0.00021279267 | BU9: 0.0059460969 | BV9: 3908 | BW9: 0 | BX9: 0 | BY9: 0.0060077968 | BZ9: 3908 | CA9: 6 | CB9: 2000
A10: 1_concurrency | B10: exp1_concurrency_G08 | C10: exp1_concurrency_g08-20261029T192019Z | D10: container | E10: synthetic | F10: 3 | G10: 2 | H10: 6 | I10: 8 | J10: capability_proportional | K10: poc_small | L10: 60 | M10: 5120 | N10: 0.075168209 | O10: 0.076184593 | P10: 99.883627 | Q10: 99.883627 | R10: 105.00811 | S10: 99.883627 | T10: 99.883627 | U10: 88.869581 | V10: 0.085001111 | W10: 0.091685224 | X10: 0.089766552 | Y10: 0.91141507 | Z10: 694 | AA10: 0 | AB10: 0 | AC10: 0 | AD10: 0.88973122 | AE10: 1.1157257 | AF10: sha256:01857acd68d2 | AG10: 42 | AH10: 32 | AI10: 8 | AJ10: 5 | AK10: 500 | AL10: 2000 | AM10: none | AN10: 0 | AO10: 0 | AP10: 39.910489 | AQ10: 79.820979 | AR10: 0.001016384 | AS10: 0 | AT10: 9.6944435 | AU10: 67.306957 | AV10: 57.612514 | AW10: 5568 | AX10: 0.09456919 | AY10: 698 | AZ10: 0 | BC10: 1.178277 | BD10: 5120 | BE10: 0 | BF10: 88.869581 | BG10: 0.085001111 | BH10: 0.089766552 | BI10: 32 | BJ10: 6 | BK10: 0.02183898 | BL10: 0.001461493 | BM10: 0.0016847951 | BN10: 5114 | BO10: 0.021889708 | BP10: 0.00064555153 | BQ10: 0.0060132389 | BR10: 5116 | BS10: 0.021760152 | BT10: 0.0006133583 | BU10: 0.0059096311 | BV10: 5118 | BW10: 0 | BX10: 0 | BY10: 0.0064599922 | BZ10: 5120 | CA10: 8 | CB10: 2000
A11: 1_concurrency | B11: exp1_concurrency_G12 | C11: exp1_concurrency_g12-20261029T192134Z | D11: container | E11: synthetic | F11: 3 | G11: 2 | H11: 6 | I11: 12 | J11: capability_proportional | K11: poc_small | L11: 60 | M11: 5162 | N11: 0.075168209 | O11: 0.076184593 | P11: 99.883627 | Q11: 99.883627 | R11: 157.51216 | S11: 99.883627 | T11: 99.883627 | U11: 89.546012 | V11: 0.12789011 | W11: 0.13188651 | X11: 0.13376891 | Y11: 0.91550242 | Z11: 696 | AA11: 0 | AB11: 0 | AC11: 0 | AD11: 0.89650341 | AE11: 1.6786873 | AF11: sha256:01857acd68d2 | AG11: 42 | AH11: 32 | AI11: 8 | AJ11: 5 | AK11: 500 | AL11: 2000 | AM11: none | AN11: 0 | AO11: 0 | AP11: 39.910489 | AQ11: 79.820979 | AR11: 0.001016384 | AS11: 0 | AT11: 9.8305986 | AU11: 67.47694 | AV11: 57.646341 | AW11: 5619 | AX11: 0.1348645 | AY11: 708 | AZ11: 0 | BC11: 1.7558525 | BD11: 5162 | BE11: 0 | BF11: 89.546012 | BG11: 0.12789011 | BH11: 0.13376891 | BI11: 44 | BJ11: 6 | BK11: 0.021819314 | BL11: 0.012061947 | BM11: 0.001735833 | BN11: 5153 | BO11: 0.021819269 | BP11: 0.0010708564 | BQ11: 0.0058462759 | BR11: 5155 | BS11: 0.022054282 | BT11: 0.033377046 | BU11: 0.0062596843 | BV11: 5160 | BW11: 0 | BX11: 0 | BY11: 0.0061745796 | BZ11: 5162 | CA11: 12 | CB11: 2000
A12: 1_concurrency | B12: exp1_concurrency_G16 | C12: exp1_concurrency_g16-20261029T192249Z | D12: container | E12: synthetic | F12: 3 | G12: 2 | H12: 6 | I12: 16 | J12: capability_proportional | K12: poc_small | L12: 60 | M12: 5318 | N12: 0.075168209 | O12: 0.076184593 | P12: 99.883627 | Q12: 99.883627 | R12: 210.01622 | S12: 99.883627 | T12: 99.883627 | U12: 92.212801 | V12: 0.16959667 | W12: 0.17353384 | X12: 0.1732968 | Y12: 0.93289501 | Z12: 704 | AA12: 0 | AB12: 0 | AC12: 0 | AD12: 0.92320237 | AE12: 2.2261282 | AF12: sha256:01857acd68d2 | AG12: 42 | AH12: 32 | AI12: 8 | AJ12: 5 | AK12: 500 | AL12: 2000 | AM12: none | AN12: 0 | AO12: 0 | AP12: 39.910489 | AQ12: 79.820979 | AR12: 0.001016384 | AS12: 0 | AT12: 8.839488 | AU12: 66.51044 | AV12: 57.670952 | AW12: 5660 | AX12: 0.17564433 | AY12: 720 | AZ12: 0 | BC12: 2.2746961 | BD12: 5318 | BE12: 0 | BF12: 92.212801 | BG12: 0.16959667 | BH12: 0.1732968 | BI12: 7 | BJ12: 6 | BK12: 0.021417169 | BL12: 0.043856387 | BM12: 0.0016807562 | BN12: 5308 | BO12: 0.021411878 | BP12: 0.022231873 | BQ12: 0.0060084319 | BR12: 5312 | BS12: 0.021413907 | BT12: 0.022088268 | BU12: 0.0059135881 | BV12: 5316 | BW12: 0 | BX12: 0 | BY12: 0.0058737523 | BZ12: 5318 | CA12: 16 | CB12: 2000
A13: 1_concurrency | B13: exp1_concurrency_G24 | C13: exp1_concurrency_g24-20261029T192403Z | D13: container | E13: synthetic | F13: 3 | G13: 2 | H13: 6 | I13: 24 | J13: capability_proportional | K13: poc_small | L13: 60 | M13: 5191 | N13: 0.075168209 | O13: 0.076184593 | P13: 99.883627 | Q13: 99.883627 | R13: 315.02432 | S13: 99.883627 | T13: 99.883627 | U13: 89.876374 | V13: 0.25527906 | W13: 0.25910437 | X13: 0.26677102 | Y13: 0.92551232 | Z13: 696 | AA13: 0 | AB13: 0 | AC13: 0 | AD13: 0.89981088 | AE13: 3.3507965 | AF13: sha256:01857acd68d2 | AG13: 42 | AH13: 32 | AI13: 8 | AJ13: 5 | AK13: 500 | AL13: 2000 | AM13: none | AN13: 0 | AO13: 0 | AP13: 39.910489 | AQ13: 79.820979 | AR13: 0.001016384 | AS13: 0 | AT13: 10.130457 | AU13: 67.887571 | AV13: 57.757114 | AW13: 5649 | AX13: 0.86666989 | AY13: 720 | AZ13: 0 | BC13: 3.50164 | BD13: 5191 | BE13: 0 | BF13: 89.876374 | BG13: 0.25527906 | BH13: 0.26677102 | BI13: 30 | BJ13: 6 | BK13: 0.021970994 | BL13: 0.13391582 | BM13: 0.0017493052 | BN13: 5181 | BO13: 0.021972037 | BP13: 0.022754648 | BQ13: 0.0060951119 | BR13: 5186 | BS13: 0.021967432 | BT13: 0.022607173 | BU13: 0.0060345405 | BV13: 5190 | BW13: 0 | BX13: 0 | BY13: 0.0062790451 | BZ13: 5191 | CA13: 24 | CB13: 2000
A14: 1_concurrency | B14: exp1_concurrency_G32 | C14: exp1_concurrency_g32-20261029T192519Z | D14: container | E14: synthetic | F14: 3 | G14: 2 | H14: 6 | I14: 32 | J14: capability_proportional | K14: poc_small | L14: 60 | M14: 5215 | N14: 0.075168209 | O14: 0.076184593 | P14: 99.883627 | Q14: 99.883627 | R14: 420.03243 | S14: 99.883627 | T14: 99.883627 | U14: 90.157296 | V14: 0.33914065 | W14: 0.34384387 | X14: 0.35472778 | Y14: 0.93330344 | Z14: 704 | AA14: 0 | AB14: 0 | AC14: 0 | AD14: 0.90262336 | AE14: 4.4515648 | AF14: sha256:01857acd68d2 | AG14: 42 | AH14: 32 | AI14: 8 | AJ14: 5 | AK14: 500 | AL14: 2000 | AM14: none | AN14: 0 | AO14: 0 | AP14: 39.910489 | AQ14: 79.820979 | AR14: 0.001016384 | AS14: 0 | AT14: 9.0171492 | AU14: 66.860499 | AV14: 57.84335 | AW14: 5673 | AX14: 0.97602772 | AY14: 736 | AZ14: 0 | BC14: 4.6561617 | BD14: 5215 | BE14: 0 | BF14: 90.157296 | BG14: 0.33914065 | BH14: 0.35472778 | BI14: 0 | BJ14: 6 | BK14: 0.021909013 | BL14: 0.23363107 | BM14: 0.0016973585 | BN14: 5206 | BO14: 0.02185976 | BP14: 0.011666757 | BQ14: 0.0061217186 | BR14: 5209 | BS14: 0.021906863 | BT14: 0.02225069 | BU14: 0.0062521636 | BV14: 5214 | BW14: 0 | BX14: 0 | BY14: 0.0060402144 | BZ14: 5215 | CA14: 32 | CB14: 2000
A15: 2_delay | B15: exp2_delay_D2_l01ms | C15: exp2_delay_d2_l01ms-20261029T192644Z | D15: container | E15: synthetic | F15: 2 | G15: 1 | H15: 2 | I15: 1 | J15: capability_proportional | K15: poc_small | L15: 45 | M15: 571 | N15: 0.062135441 | O15: 0.063151825 | P15: 33.294542 | Q15: 16.647271 | R15: 15.834855 | S15: 33.294542 | T15: 15.834855 | U15: 13.836299 | V15: 0.069268227 | W15: 0.074574232 | X15: 0.072015599 | Y15: 0.41593166 | Z15: 80 | AA15: 0 | AB15: 0 | AC15: 0 | AD15: 0.41557259 | AE15: 1.0968523 | AF15: sha256:01857acd68d2 | AG15: 42 | AH15: 32 | AI15: 8 | AJ15: 5 | AK15: 500 | AL15: 2000 | AM15: none | AN15: 0 | AO15: 0 | AP15: 32.187749 | AQ15: 32.187749 | AR15: 0.001016384 | AS15: 0 | AT15: 9.1516058 | AU15: 50.419867 | AV15: 41.268261 | AW15: 641 | AX15: 0.079121637 | AY15: 81 | AZ15: 0 | BC15: 1.1403566 | BD15: 571 | BE15: 0 | BF15: 13.836299 | BG15: 0.069268227 | BH15: 0.072015599 | BI15: 2 | BJ15: 2 | BK15: 0.033364083 | BL15: 0.00018493334 | BM15: 0.0018615919 | BN15: 570 | BO15: 0.031191804 | BP15: 0.0001791473 | BQ15: 0.0018760259 | BR15: 570 | BS15: 0 | BT15: 0 | BU15: 0.0019713688 | BV15: 571 | CC15: 2 | CD15: 1
